Workbook

Sheet Alocări
A1: Client | B1: Proiect | C1: Persoană | D1: Rol | E1: Mai 2026 (h) | F1: Iun 2026 (h) | G1: Iul 2026 (h) | H1: Aug 2026 (h) | I1: Sep 2026 (h) | J1: Oct 2026 (h) | K1: Nov 2026 (h) | L1: Dec 2026 (h)
A2: Advance | B2: Mentenanta | C2: Tudor Caraciuc | D2: PM | E2: 0 | F2: 0 | G2: 3 | H2: 3 | I2: 3 | J2: 3 | K2: 3 | L2: 3 | M2: =SUM(E2:L2) -> 18
A3: BT Leasing | B3: BT Leasing - CSP | C3: Alex Mateiu | D3: PM | E3: 0 | F3: 0 | G3: 0 | H3: 20 | I3: 20 | J3: 20 | K3: 20 | L3: 20 | M3: =SUM(E3:L3) -> 100
A4: BT Leasing | B4: BT Leasing - CSP | C4: Alexandra Negruti | D4: FE Dev | E4: 0 | F4: 0 | G4: 0 | H4: 20 | I4: 20 | J4: 20 | K4: 20 | L4: 20 | M4: =SUM(E4:L4) -> 100
A5: BT Leasing | B5: BT Leasing - CSP | C5: George Popescu | D5: BE Dev | E5: 0 | F5: 0 | G5: 0 | H5: 60 | I5: 60 | J5: 60 | K5: 60 | L5: 60 | M5: =SUM(E5:L5) -> 300
A6: BT Leasing | B6: BT Leasing - CSP | C6: Ioana Bolboaca | D6: PM | E6: 0 | F6: 0 | G6: 20 | H6: 20 | I6: 20 | J6: 20 | K6: 20 | L6: 20
A7: BT Leasing | B7: BT Leasing - CSP | C7: Tudor Caraciuc | D7: PM | E7: 0 | F7: 0 | G7: 40 | H7: 40 | I7: 40 | J7: 40 | K7: 40 | L7: 40 | M7: =SUM(E7:L7) -> 240
A8: Connect Experiences | B8: Mentenanta | C8: Alex Mateiu | D8: PM | E8: 0 | F8: 0 | G8: 3 | H8: 3 | I8: 3 | J8: 3 | K8: 3 | L8: 3 | M8: =SUM(E8:L8) -> 18
A9: Connect Experiences | B9: Mentenanta | C9: George Popescu | D9: BE Dev | E9: 0 | F9: 0 | G9: 3 | H9: 3 | I9: 3 | J9: 3 | K9: 3 | L9: 3 | M9: =SUM(E9:L9) -> 18
A10: Dialectica | B10: Mentenanta | C10: Alex Mateiu | D10: QA | E10: 20.7 | F10: 20.7 | G10: 20.7 | H10: 20.7 | I10: 20.7 | J10: 20.7 | K10: 20.7 | L10: 20.7 | M10: =SUM(E10:L10) -> 165.6
A11: Dialectica | B11: Mentenanta | C11: Alexandra Negruti | D11: FE Dev | E11: 20.7 | F11: 20.7 | G11: 20.7 | H11: 20.7 | I11: 20.7 | J11: 20.7 | K11: 20.7 | L11: 20.7 | M11: =SUM(E11:L11) -> 165.6
A12: Dialectica | B12: Mentenanta | C12: Dan Dima | D12: PM | E12: 13.8 | F12: 13.8 | G12: 13.8 | H12: 13.8 | I12: 13.8 | J12: 13.8 | K12: 13.8 | L12: 13.8 | M12: =SUM(E12:L12) -> 110.4
A13: Dialectica | B13: Mentenanta | C13: Dan Dima | D13: BA | E13: 13.8 | F13: 13.8 | G13: 13.8 | H13: =13.8+20.7 -> 34.5 | I13: =13.8+20.7 -> 34.5 | J13: =13.8+20.7 -> 34.5 | K13: =13.8+20.7 -> 34.5 | L13: =13.8+20.7 -> 34.5 | M13: =SUM(E13:L13) -> 213.9
A14: Dialectica | B14: Mentenanta | C14: Mihai Scurtu | D14: BE Dev | E14: 20.7 | F14: 20.7 | G14: 20.7 | M14: =SUM(E14:L14) -> 62.1
A15: Dialectica | B15: Mentenanta | C15: Tudor Caraciuc | D15: BE Dev | E15: 124.2 | F15: 20.7 | G15: 20.7 | H15: 20.7 | I15: 20.7 | J15: 20.7 | K15: 20.7 | L15: 20.7 | M15: =SUM(E15:L15) -> 269.1
A16: Dialectica | B16: Extra Dev | C16: Alexandra Negruti | D16: FE Dev | G16: 20 | H16: 20 | I16: 20 | J16: 20 | K16: 20 | L16: 20 | M16: =SUM(E16:L16) -> 120
A17: Dialectica | B17: Extra Dev | C17: Tudor Caraciuc | D17: PM | G17: 50 | H17: 50 | I17: 50 | J17: 50 | K17: 50 | L17: 50 | M17: =SUM(E17:L17) -> 300
A18: Dialectica | B18: Extra Dev | C18: Dan Dima | D18: BE Dev | G18: 50 | H18: 50 | I18: 50 | J18: 50 | K18: 50 | L18: 50 | M18: =SUM(E18:L18) -> 300
A19: Dtangle | B19: Dtangle SGDL | C19: Claudiu Florea | D19: BE Dev | E19: 40 | F19: 80 | G19: 80 | H19: 8 | I19: 8 | J19: 8 | K19: 8 | L19: 8 | M19: =SUM(E19:L19) -> 240
A20: Dtangle | B20: Dtangle SGDL | C20: Dan Dima | D20: PM | E20: 0 | F20: 0 | G20: 0 | H20: 8 | I20: 8 | J20: 8 | K20: 8 | L20: 8 | M20: =SUM(E20:L20) -> 40
A21: Dtangle | B21: Dtangle SGDL | C21: Stefan Oprea | D21: Ai Engineer | E21: 34.5 | F21: 69 | G21: 69 | H21: 56 | I21: 28 | J21: 56 | K21: 28 | L21: 56 | M21: =SUM(E21:L21) -> 396.5
A22: Iancu Guda | B22: MiM Mentenanta | C22: Alex Mateiu | D22: PM | E22: 0 | F22: 17.2 | G22: 8 | H22: 8 | I22: 8 | J22: 8 | K22: 8 | L22: 8 | M22: =SUM(E22:L22) -> 65.2
A23: Iancu Guda | B23: MiM Mentenanta | C23: Alex Mateiu | D23: BA | E23: 8.3 | F23: 20.7 | G23: 0 | H23: 0 | I23: 0 | J23: 0 | K23: 0 | L23: 0 | M23: =SUM(E23:L23) -> 29
A24: Iancu Guda | B24: MiM Mentenanta | C24: Alex Mateiu | D24: QA | E24: 13.8 | F24: 34.5 | G24: 0 | H24: 0 | I24: 0 | J24: 0 | K24: 0 | L24: 0 | M24: =SUM(E24:L24) -> 48.3
A25: Iancu Guda | B25: MiM Mentenanta | C25: Alexandra Negruti | D25: FE Dev | E25: 34.5 | F25: 69 | G25: 5 | H25: 5 | I25: 5 | J25: 5 | K25: 5 | L25: 5 | M25: =SUM(E25:L25) -> 133.5
A26: Iancu Guda | B26: MiM Mentenanta | C26: Calin Stefanescu | D26: UX/UI | E26: 13.8 | F26: 34.5 | G26: 16 | H26: 0 | I26: 0 | J26: 0 | K26: 0 | L26: 0 | M26: =SUM(E26:L26) -> 64.3
A27: Iancu Guda | B27: MiM Mentenanta | C27: Dragoș Burciu | D27: BE Dev | E27: 37.3 | F27: 51.8 | G27: 8 | H27: 8 | I27: 8 | J27: 8 | K27: 8 | L27: 8 | M27: =SUM(E27:L27) -> 137.1
A28: Iancu Guda | B28: MiM Mentenanta | C28: George Popescu | D28: BE Dev | E28: 19.3 | F28: 48.3 | G28: 4 | H28: 4 | I28: 4 | J28: 4 | K28: 4 | L28: 4 | M28: =SUM(E28:L28) -> 91.6
A29: Iancu Guda | B29: MiM DEV | C29: Alex Mateiu | D29: PM | G29: 10 | H29: 10 | I29: 10 | M29: =SUM(E29:L29) -> 30
A30: Iancu Guda | B30: MiM DEV | C30: Alex Mateiu | D30: QA | G30: 20 | H30: 20 | I30: 20 | M30: =SUM(E30:L30) -> 60
A31: Iancu Guda | B31: MiM DEV | C31: George Popescu | D31: BE Dev | G31: 96 | H31: 49 | I31: 96 | M31: =SUM(E31:L31) -> 241
A32: Iancu Guda | B32: MiM DEV | C32: Pierina Giusiano | D32: FE Dev | E32: 0 | F32: 51.8 | G32: 30 | H32: 30 | I32: 30 | J32: 29 | M32: =SUM(E32:L32) -> 170.8
A33: Iancu Guda | B33: MiM DEV | C33: Dragoș Burciu | D33: BE Dev | G33: 6 | H33: 6 | I33: 6 | M33: =SUM(E33:L33) -> 18
A34: Iancu Guda | B34: MiM DEV | C34: Pierina Giusiano | D34: QA | E34: 13.8 | F34: 34.5 | M34: =SUM(E34:L34) -> 48.3
A35: Nep Services | B35: Nep Services - Mentenanta / Arch | C35: Bogdan Duda | D35: Architect | E35: 8.8 | F35: 0 | G35: 8 | H35: 8 | I35: 8 | J35: 8 | K35: 8 | L35: 8 | M35: =SUM(E35:L35) -> 56.8
A36: Osiris | B36: La Depozit | C36: Alex Mateiu | D36: QA | E36: 26.2 | F36: 0 | G36: 0 | H36: 0 | I36: 0 | J36: 0 | K36: 0 | L36: 0 | M36: =SUM(E36:L36) -> 26.2
A37: Osiris | B37: La Depozit | C37: Dragoș Burciu | D37: BE Dev | E37: 95.2 | F37: 75.9 | G37: 100 | H37: 100 | I37: 100 | J37: 100 | K37: 100 | L37: 100 | M37: =SUM(E37:L37) -> 771.1
A38: Osiris | B38: La Depozit | C38: George Popescu | D38: BE Dev | E38: 29 | F38: 20.7 | G38: 20.7 | H38: 0 | I38: 0 | J38: 0 | K38: 0 | L38: 0 | M38: =SUM(E38:L38) -> 70.4
A39: Osiris | B39: La Depozit | C39: Pierina Giusiano | D39: FE Dev | E39: 55.2 | F39: 17.2 | G39: 0 | H39: 0 | I39: 0 | J39: 0 | K39: 0 | L39: 0 | M39: =SUM(E39:L39) -> 72.4
A40: Osiris | B40: La Depozit | C40: Pierina Giusiano | D40: QA | E40: 27.6 | F40: 34.5 | G40: 34.5 | H40: 0 | I40: 0 | J40: 0 | K40: 0 | L40: 0 | M40: =SUM(E40:L40) -> 96.6
...

Sheet Pe persoană
A1: Persoană | B1: Normă (h/lună) | C1: Mai 2026 (h) | D1: Iun 2026 (h) | E1: Iul 2026 (h) | F1: Aug 2026 (h) | G1: Sep 2026 (h) | H1: Oct 2026 (h) | I1: Nov 2026 (h) | J1: Dec 2026 (h)
A2: Alex Mateiu | B2: 138 | C2: =SUMIF('Alocări'!$C$2:$C$61,$A2,'Alocări'!E$2:E$61) -> 82.8 | D2: =SUMIF('Alocări'!$C$2:$C$61,$A2,'Alocări'!F$2:F$61) -> 117.2 | E2: =SUMIF('Alocări'!$C$2:$C$61,$A2,'Alocări'!G$2:G$61) -> 61.7 | F2: =SUMIF('Alocări'!$C$2:$C$61,$A2,'Alocări'!H$2:H$61) -> 81.7 | G2: =SUMIF('Alocări'!$C$2:$C$61,$A2,'Alocări'!I$2:I$61) -> 81.7 | H2: =SUMIF('Alocări'!$C$2:$C$61,$A2,'Alocări'!J$2:J$61) -> 51.7 | I2: =SUMIF('Alocări'!$C$2:$C$61,$A2,'Alocări'!K$2:K$61) -> 51.7 | J2: =SUMIF('Alocări'!$C$2:$C$61,$A2,'Alocări'!L$2:L$61) -> 51.7
A3: Alexandra Negruti | B3: 138 | C3: =SUMIF('Alocări'!$C$2:$C$61,$A3,'Alocări'!E$2:E$61) -> 103.5 | D3: =SUMIF('Alocări'!$C$2:$C$61,$A3,'Alocări'!F$2:F$61) -> 124.2 | E3: =SUMIF('Alocări'!$C$2:$C$61,$A3,'Alocări'!G$2:G$61) -> 45.7 | F3: =SUMIF('Alocări'!$C$2:$C$61,$A3,'Alocări'!H$2:H$61) -> 65.7 | G3: =SUMIF('Alocări'!$C$2:$C$61,$A3,'Alocări'!I$2:I$61) -> 65.7 | H3: =SUMIF('Alocări'!$C$2:$C$61,$A3,'Alocări'!J$2:J$61) -> 65.7 | I3: =SUMIF('Alocări'!$C$2:$C$61,$A3,'Alocări'!K$2:K$61) -> 65.7 | J3: =SUMIF('Alocări'!$C$2:$C$61,$A3,'Alocări'!L$2:L$61) -> 65.7
A4: Bogdan Duda | B4: 118 | C4: =SUMIF('Alocări'!$C$2:$C$61,$A4,'Alocări'!E$2:E$61) -> 88.4 | D4: =SUMIF('Alocări'!$C$2:$C$61,$A4,'Alocări'!F$2:F$61) -> 79.6 | E4: =SUMIF('Alocări'!$C$2:$C$61,$A4,'Alocări'!G$2:G$61) -> 34.5 | F4: =SUMIF('Alocări'!$C$2:$C$61,$A4,'Alocări'!H$2:H$61) -> 8 | G4: =SUMIF('Alocări'!$C$2:$C$61,$A4,'Alocări'!I$2:I$61) -> 8 | H4: =SUMIF('Alocări'!$C$2:$C$61,$A4,'Alocări'!J$2:J$61) -> 8 | I4: =SUMIF('Alocări'!$C$2:$C$61,$A4,'Alocări'!K$2:K$61) -> 8 | J4: =SUMIF('Alocări'!$C$2:$C$61,$A4,'Alocări'!L$2:L$61) -> 8
A5: Calin Stefanescu | B5: 138 | C5: =SUMIF('Alocări'!$C$2:$C$61,$A5,'Alocări'!E$2:E$61) -> 82.8 | D5: =SUMIF('Alocări'!$C$2:$C$61,$A5,'Alocări'!F$2:F$61) -> 103.5 | E5: 85 | F5: 0 | G5: =SUMIF('Alocări'!$C$2:$C$61,$A5,'Alocări'!I$2:I$61) -> 0 | H5: =SUMIF('Alocări'!$C$2:$C$61,$A5,'Alocări'!J$2:J$61) -> 0 | I5: =SUMIF('Alocări'!$C$2:$C$61,$A5,'Alocări'!K$2:K$61) -> 0 | J5: =SUMIF('Alocări'!$C$2:$C$61,$A5,'Alocări'!L$2:L$61) -> 0
A6: Claudiu Florea | B6: 160 | C6: =SUMIF('Alocări'!$C$2:$C$61,$A6,'Alocări'!E$2:E$61) -> 40 | D6: =SUMIF('Alocări'!$C$2:$C$61,$A6,'Alocări'!F$2:F$61) -> 80 | E6: =SUMIF('Alocări'!$C$2:$C$61,$A6,'Alocări'!G$2:G$61) -> 80 | F6: =SUMIF('Alocări'!$C$2:$C$61,$A6,'Alocări'!H$2:H$61) -> 8 | G6: =SUMIF('Alocări'!$C$2:$C$61,$A6,'Alocări'!I$2:I$61) -> 8 | H6: =SUMIF('Alocări'!$C$2:$C$61,$A6,'Alocări'!J$2:J$61) -> 8 | I6: =SUMIF('Alocări'!$C$2:$C$61,$A6,'Alocări'!K$2:K$61) -> 8 | J6: =SUMIF('Alocări'!$C$2:$C$61,$A6,'Alocări'!L$2:L$61) -> 8
A7: Dan Dima | B7: 138 | C7: =SUMIF('Alocări'!$C$2:$C$61,$A7,'Alocări'!E$2:E$61) -> 131.1 | D7: =SUMIF('Alocări'!$C$2:$C$61,$A7,'Alocări'!F$2:F$61) -> 131.1 | E7: =SUMIF('Alocări'!$C$2:$C$61,$A7,'Alocări'!G$2:G$61) -> 107.6 | F7: =SUMIF('Alocări'!$C$2:$C$61,$A7,'Alocări'!H$2:H$61) -> 122.3 | G7: =SUMIF('Alocări'!$C$2:$C$61,$A7,'Alocări'!I$2:I$61) -> 106.3 | H7: =SUMIF('Alocări'!$C$2:$C$61,$A7,'Alocări'!J$2:J$61) -> 106.3 | I7: =SUMIF('Alocări'!$C$2:$C$61,$A7,'Alocări'!K$2:K$61) -> 106.3 | J7: =SUMIF('Alocări'!$C$2:$C$61,$A7,'Alocări'!L$2:L$61) -> 106.3
A8: Dinu Taleanu | B8: 108 | C8: =SUMIF('Alocări'!$C$2:$C$61,$A8,'Alocări'!E$2:E$61) -> 120 | D8: =SUMIF('Alocări'!$C$2:$C$61,$A8,'Alocări'!F$2:F$61) -> 120 | E8: =SUMIF('Alocări'!$C$2:$C$61,$A8,'Alocări'!G$2:G$61) -> 120 | F8: =SUMIF('Alocări'!$C$2:$C$61,$A8,'Alocări'!H$2:H$61) -> 120 | G8: =SUMIF('Alocări'!$C$2:$C$61,$A8,'Alocări'!I$2:I$61) -> 0 | H8: =SUMIF('Alocări'!$C$2:$C$61,$A8,'Alocări'!J$2:J$61) -> 0 | I8: =SUMIF('Alocări'!$C$2:$C$61,$A8,'Alocări'!K$2:K$61) -> 0 | J8: =SUMIF('Alocări'!$C$2:$C$61,$A8,'Alocări'!L$2:L$61) -> 0
A9: Dragoș Burciu | B9: 138 | C9: =SUMIF('Alocări'!$C$2:$C$61,$A9,'Alocări'!E$2:E$61) -> 132.5 | D9: =SUMIF('Alocări'!$C$2:$C$61,$A9,'Alocări'!F$2:F$61) -> 127.7 | E9: =SUMIF('Alocări'!$C$2:$C$61,$A9,'Alocări'!G$2:G$61) -> 114 | F9: =SUMIF('Alocări'!$C$2:$C$61,$A9,'Alocări'!H$2:H$61) -> 114 | G9: =SUMIF('Alocări'!$C$2:$C$61,$A9,'Alocări'!I$2:I$61) -> 114 | H9: =SUMIF('Alocări'!$C$2:$C$61,$A9,'Alocări'!J$2:J$61) -> 108 | I9: =SUMIF('Alocări'!$C$2:$C$61,$A9,'Alocări'!K$2:K$61) -> 108 | J9: =SUMIF('Alocări'!$C$2:$C$61,$A9,'Alocări'!L$2:L$61) -> 108
A10: George Popescu | B10: 138 | C10: =SUMIF('Alocări'!$C$2:$C$61,$A10,'Alocări'!E$2:E$61) -> 138 | D10: =SUMIF('Alocări'!$C$2:$C$61,$A10,'Alocări'!F$2:F$61) -> 138 | E10: =SUMIF('Alocări'!$C$2:$C$61,$A10,'Alocări'!G$2:G$61) -> 185.7 | F10: =SUMIF('Alocări'!$C$2:$C$61,$A10,'Alocări'!H$2:H$61) -> 120 | G10: =SUMIF('Alocări'!$C$2:$C$61,$A10,'Alocări'!I$2:I$61) -> 167 | H10: =SUMIF('Alocări'!$C$2:$C$61,$A10,'Alocări'!J$2:J$61) -> 71 | I10: =SUMIF('Alocări'!$C$2:$C$61,$A10,'Alocări'!K$2:K$61) -> 71 | J10: =SUMIF('Alocări'!$C$2:$C$61,$A10,'Alocări'!L$2:L$61) -> 71
A11: Ioana Bolboaca | B11: 138 | C11: =SUMIF('Alocări'!$C$2:$C$61,$A11,'Alocări'!E$2:E$61) -> 62.1 | D11: =SUMIF('Alocări'!$C$2:$C$61,$A11,'Alocări'!F$2:F$61) -> 62.1 | E11: =SUMIF('Alocări'!$C$2:$C$61,$A11,'Alocări'!G$2:G$61) -> 58.3 | F11: =SUMIF('Alocări'!$C$2:$C$61,$A11,'Alocări'!H$2:H$61) -> 64.7 | G11: =SUMIF('Alocări'!$C$2:$C$61,$A11,'Alocări'!I$2:I$61) -> 44 | H11: =SUMIF('Alocări'!$C$2:$C$61,$A11,'Alocări'!J$2:J$61) -> 44 | I11: =SUMIF('Alocări'!$C$2:$C$61,$A11,'Alocări'!K$2:K$61) -> 44 | J11: =SUMIF('Alocări'!$C$2:$C$61,$A11,'Alocări'!L$2:L$61) -> 44
A12: Mihai Scurtu | B12: 138 | C12: =SUMIF('Alocări'!$C$2:$C$61,$A12,'Alocări'!E$2:E$61) -> 20.7 | D12: =SUMIF('Alocări'!$C$2:$C$61,$A12,'Alocări'!F$2:F$61) -> 20.7 | E12: =SUMIF('Alocări'!$C$2:$C$61,$A12,'Alocări'!G$2:G$61) -> 20.7 | F12: =SUMIF('Alocări'!$C$2:$C$61,$A12,'Alocări'!H$2:H$61) -> 0 | G12: =SUMIF('Alocări'!$C$2:$C$61,$A12,'Alocări'!I$2:I$61) -> 0 | H12: =SUMIF('Alocări'!$C$2:$C$61,$A12,'Alocări'!J$2:J$61) -> 0 | I12: =SUMIF('Alocări'!$C$2:$C$61,$A12,'Alocări'!K$2:K$61) -> 0 | J12: =SUMIF('Alocări'!$C$2:$C$61,$A12,'Alocări'!L$2:L$61) -> 0
A13: Pierina Giusiano | B13: 138 | C13: =SUMIF('Alocări'!$C$2:$C$61,$A13,'Alocări'!E$2:E$61) -> 96.6 | D13: =SUMIF('Alocări'!$C$2:$C$61,$A13,'Alocări'!F$2:F$61) -> 138 | E13: =SUMIF('Alocări'!$C$2:$C$61,$A13,'Alocări'!G$2:G$61) -> 64.5 | F13: =SUMIF('Alocări'!$C$2:$C$61,$A13,'Alocări'!H$2:H$61) -> 30 | G13: =SUMIF('Alocări'!$C$2:$C$61,$A13,'Alocări'!I$2:I$61) -> 30 | H13: =SUMIF('Alocări'!$C$2:$C$61,$A13,'Alocări'!J$2:J$61) -> 29 | I13: =SUMIF('Alocări'!$C$2:$C$61,$A13,'Alocări'!K$2:K$61) -> 0 | J13: =SUMIF('Alocări'!$C$2:$C$61,$A13,'Alocări'!L$2:L$61) -> 0
A14: Simona Burciu | B14: 138 | C14: =SUMIF('Alocări'!$C$2:$C$61,$A14,'Alocări'!E$2:E$61) -> 69 | D14: =SUMIF('Alocări'!$C$2:$C$61,$A14,'Alocări'!F$2:F$61) -> 69 | E14: =SUMIF('Alocări'!$C$2:$C$61,$A14,'Alocări'!G$2:G$61) -> 80 | F14: =SUMIF('Alocări'!$C$2:$C$61,$A14,'Alocări'!H$2:H$61) -> 80 | G14: =SUMIF('Alocări'!$C$2:$C$61,$A14,'Alocări'!I$2:I$61) -> 80 | H14: =SUMIF('Alocări'!$C$2:$C$61,$A14,'Alocări'!J$2:J$61) -> 80 | I14: =SUMIF('Alocări'!$C$2:$C$61,$A14,'Alocări'!K$2:K$61) -> 80 | J14: =SUMIF('Alocări'!$C$2:$C$61,$A14,'Alocări'!L$2:L$61) -> 80
A15: Stefan Oprea | B15: 138 | C15: =SUMIF('Alocări'!$C$2:$C$61,$A15,'Alocări'!E$2:E$61) -> 138 | D15: =SUMIF('Alocări'!$C$2:$C$61,$A15,'Alocări'!F$2:F$61) -> 138 | E15: =SUMIF('Alocări'!$C$2:$C$61,$A15,'Alocări'!G$2:G$61) -> 229 | F15: =SUMIF('Alocări'!$C$2:$C$61,$A15,'Alocări'!H$2:H$61) -> 176 | G15: =SUMIF('Alocări'!$C$2:$C$61,$A15,'Alocări'!I$2:I$61) -> 28 | H15: =SUMIF('Alocări'!$C$2:$C$61,$A15,'Alocări'!J$2:J$61) -> 56 | I15: =SUMIF('Alocări'!$C$2:$C$61,$A15,'Alocări'!K$2:K$61) -> 28 | J15: =SUMIF('Alocări'!$C$2:$C$61,$A15,'Alocări'!L$2:L$61) -> 56
A16: Tudor Caraciuc | B16: 138 | C16: =SUMIF('Alocări'!$C$2:$C$61,$A16,'Alocări'!E$2:E$61) -> 124.2 | D16: =SUMIF('Alocări'!$C$2:$C$61,$A16,'Alocări'!F$2:F$61) -> 20.7 | E16: =SUMIF('Alocări'!$C$2:$C$61,$A16,'Alocări'!G$2:G$61) -> 153.7 | F16: =SUMIF('Alocări'!$C$2:$C$61,$A16,'Alocări'!H$2:H$61) -> 113.7 | G16: =SUMIF('Alocări'!$C$2:$C$61,$A16,'Alocări'!I$2:I$61) -> 113.7 | H16: =SUMIF('Alocări'!$C$2:$C$61,$A16,'Alocări'!J$2:J$61) -> 113.7 | I16: =SUMIF('Alocări'!$C$2:$C$61,$A16,'Alocări'!K$2:K$61) -> 113.7 | J16: =SUMIF('Alocări'!$C$2:$C$61,$A16,'Alocări'!L$2:L$61) -> 113.7
